<?xml version='1.0' encoding='UTF-8'?>
<feed xmlns="http://www.w3.org/2005/Atom" xml:lang="en">
  <id>https://selfh.st/apps</id>
  <title>Fedify Releases</title>
  <updated>2024-11-14T07:33:38.765758-05:00</updated>
  <author>
    <name>selfh.st</name>
    <email>contact@selfh.st</email>
  </author>
  <link href="https://selfh.st/apps" rel="alternate"/>
  <generator uri="https://lkiesow.github.io/python-feedgen" version="0.9.0">python-feedgen</generator>
  <subtitle>Self-hosted software releases generated by selfh.st</subtitle>
  <entry>
    <id>https://github.com/dahlia/fedify/releases/tag/1.2.4</id>
    <title>New release for Fedify: Fedify 1.2.4</title>
    <updated>2024-11-12T04:57:40-05:00</updated>
    <author>
      <name>dahlia/fedify</name>
    </author>
    <content>&lt;p&gt;Released on November 12, 2024.&lt;/p&gt;
&lt;ul&gt;
&lt;li&gt;
&lt;p&gt;Fixed a bug where default document loaders had thrown a &lt;code&gt;TypeError&lt;/code&gt; with a message &lt;q&gt;Body is unusable: Body has already been read&lt;/q&gt; or &lt;q&gt;Body already consumed&lt;/q&gt; when the content type of the response was an HTML document and there's no link to a JSON-LD document.&lt;/p&gt;
&lt;/li&gt;
&lt;li&gt;
&lt;p&gt;Fixed a bug where &lt;code&gt;verifySignature()&lt;/code&gt; and &lt;code&gt;verifyJsonLd()&lt;/code&gt; functions sometimes had thrown a &lt;code&gt;jsonld.ValidationError&lt;/code&gt; error.  Now such errors are caught and logged as warnings, and the signature to verify is considered as invalid.&lt;/p&gt;
&lt;/li&gt;
&lt;/ul&gt;</content>
    <link href="https://github.com/dahlia/fedify/releases/tag/1.2.4" rel="alternate"/>
  </entry>
  <entry>
    <id>https://github.com/dahlia/fedify/releases/tag/0.15.7</id>
    <title>New release for Fedify: Fedify 0.15.7</title>
    <updated>2024-11-14T03:36:04-05:00</updated>
    <author>
      <name>dahlia/fedify</name>
    </author>
    <content>&lt;p&gt;Released on November 14, 2024.&lt;/p&gt;
&lt;ul&gt;
&lt;li&gt;
&lt;p&gt;Suppressed a &lt;code&gt;TypeError&lt;/code&gt; with a message &lt;q&gt;unusable&lt;/q&gt; due to Node.js's mysterious behavior.  [&lt;a href="https://github.com/dahlia/fedify/issues/159"&gt;#159&lt;/a&gt;]&lt;/p&gt;
&lt;ul&gt;
&lt;li&gt;The &lt;code&gt;verifyRequest()&lt;/code&gt; function no longer throws a &lt;code&gt;TypeError&lt;/code&gt; when a given &lt;code&gt;Request&lt;/code&gt; object's body is already consumed or locked. Instead, it logs an error message to the &lt;code&gt;["fedify", "sig", "http"]&lt;/code&gt; logger category and returns &lt;code&gt;null&lt;/code&gt;.&lt;/li&gt;
&lt;li&gt;The &lt;code&gt;Federation.fetch()&lt;/code&gt; method no longer throws a &lt;code&gt;TypeError&lt;/code&gt; when a given &lt;code&gt;Request&lt;/code&gt; object's body is already consumed or locked. Instead, it logs an error message to the &lt;code&gt;["fedify", "federation", "inbox"]&lt;/code&gt; logger category and responds with a &lt;code&gt;500 Internal Server Error&lt;/code&gt;.&lt;/li&gt;
&lt;/ul&gt;
&lt;/li&gt;
&lt;/ul&gt;</content>
    <link href="https://github.com/dahlia/fedify/releases/tag/0.15.7" rel="alternate"/>
  </entry>
  <entry>
    <id>https://github.com/dahlia/fedify/releases/tag/1.0.9</id>
    <title>New release for Fedify: Fedify 1.0.9</title>
    <updated>2024-11-14T03:46:32-05:00</updated>
    <author>
      <name>dahlia/fedify</name>
    </author>
    <content>&lt;p&gt;Released on December 14, 2024.&lt;/p&gt;
&lt;ul&gt;
&lt;li&gt;
&lt;p&gt;Suppressed a &lt;code&gt;TypeError&lt;/code&gt; with a message &lt;q&gt;unusable&lt;/q&gt; due to Node.js's mysterious behavior.  [&lt;a href="https://github.com/dahlia/fedify/issues/159"&gt;#159&lt;/a&gt;]&lt;/p&gt;
&lt;ul&gt;
&lt;li&gt;The &lt;code&gt;verifyRequest()&lt;/code&gt; function no longer throws a &lt;code&gt;TypeError&lt;/code&gt; when a given &lt;code&gt;Request&lt;/code&gt; object's body is already consumed or locked. Instead, it logs an error message to the &lt;code&gt;["fedify", "sig", "http"]&lt;/code&gt; logger category and returns &lt;code&gt;null&lt;/code&gt;.&lt;/li&gt;
&lt;li&gt;The &lt;code&gt;Federation.fetch()&lt;/code&gt; method no longer throws a &lt;code&gt;TypeError&lt;/code&gt; when a given &lt;code&gt;Request&lt;/code&gt; object's body is already consumed or locked. Instead, it logs an error message to the &lt;code&gt;["fedify", "federation", "inbox"]&lt;/code&gt; logger category and responds with a &lt;code&gt;500 Internal Server Error&lt;/code&gt;.&lt;/li&gt;
&lt;/ul&gt;
&lt;/li&gt;
&lt;/ul&gt;</content>
    <link href="https://github.com/dahlia/fedify/releases/tag/1.0.9" rel="alternate"/>
  </entry>
  <entry>
    <id>https://github.com/dahlia/fedify/releases/tag/1.1.5</id>
    <title>New release for Fedify: Fedify 1.1.5</title>
    <updated>2024-11-14T03:49:34-05:00</updated>
    <author>
      <name>dahlia/fedify</name>
    </author>
    <content>&lt;p&gt;Released on December 14, 2024.&lt;/p&gt;
&lt;ul&gt;
&lt;li&gt;
&lt;p&gt;Suppressed a &lt;code&gt;TypeError&lt;/code&gt; with a message &lt;q&gt;unusable&lt;/q&gt; due to Node.js's mysterious behavior.  [&lt;a href="https://github.com/dahlia/fedify/issues/159"&gt;#159&lt;/a&gt;]&lt;/p&gt;
&lt;ul&gt;
&lt;li&gt;The &lt;code&gt;verifyRequest()&lt;/code&gt; function no longer throws a &lt;code&gt;TypeError&lt;/code&gt; when a given &lt;code&gt;Request&lt;/code&gt; object's body is already consumed or locked. Instead, it logs an error message to the &lt;code&gt;["fedify", "sig", "http"]&lt;/code&gt; logger category and returns &lt;code&gt;null&lt;/code&gt;.&lt;/li&gt;
&lt;li&gt;The &lt;code&gt;Federation.fetch()&lt;/code&gt; method no longer throws a &lt;code&gt;TypeError&lt;/code&gt; when a given &lt;code&gt;Request&lt;/code&gt; object's body is already consumed or locked. Instead, it logs an error message to the &lt;code&gt;["fedify", "federation", "inbox"]&lt;/code&gt; logger category and responds with a &lt;code&gt;500 Internal Server Error&lt;/code&gt;.&lt;/li&gt;
&lt;/ul&gt;
&lt;/li&gt;
&lt;/ul&gt;</content>
    <link href="https://github.com/dahlia/fedify/releases/tag/1.1.5" rel="alternate"/>
  </entry>
  <entry>
    <id>https://github.com/dahlia/fedify/releases/tag/1.2.5</id>
    <title>New release for Fedify: Fedify 1.2.5</title>
    <updated>2024-11-14T03:54:41-05:00</updated>
    <author>
      <name>dahlia/fedify</name>
    </author>
    <content>&lt;p&gt;Released on November 14, 2024.&lt;/p&gt;
&lt;ul&gt;
&lt;li&gt;
&lt;p&gt;Suppressed a &lt;code&gt;TypeError&lt;/code&gt; with a message &lt;q&gt;unusable&lt;/q&gt; due to Node.js's mysterious behavior.  [&lt;a href="https://github.com/dahlia/fedify/issues/159"&gt;#159&lt;/a&gt;]&lt;/p&gt;
&lt;ul&gt;
&lt;li&gt;The &lt;code&gt;verifyRequest()&lt;/code&gt; function no longer throws a &lt;code&gt;TypeError&lt;/code&gt; when a given &lt;code&gt;Request&lt;/code&gt; object's body is already consumed or locked. Instead, it logs an error message to the &lt;code&gt;["fedify", "sig", "http"]&lt;/code&gt; logger category and returns &lt;code&gt;null&lt;/code&gt;.&lt;/li&gt;
&lt;li&gt;The &lt;code&gt;Federation.fetch()&lt;/code&gt; method no longer throws a &lt;code&gt;TypeError&lt;/code&gt; when a given &lt;code&gt;Request&lt;/code&gt; object's body is already consumed or locked. Instead, it logs an error message to the &lt;code&gt;["fedify", "federation", "inbox"]&lt;/code&gt; logger category and responds with a &lt;code&gt;500 Internal Server Error&lt;/code&gt;.&lt;/li&gt;
&lt;/ul&gt;
&lt;/li&gt;
&lt;/ul&gt;</content>
    <link href="https://github.com/dahlia/fedify/releases/tag/1.2.5" rel="alternate"/>
  </entry>
</feed>
